Traceback (most recent call last):
  File "C:\Users\vg8rw\OneDrive\桌面\project\Test\test\Lib\site-packages\sqlalchemy\engine\base.py", line 146, in __init__
    self._dbapi_connection = engine.raw_connection()
                             ^^^^^^^^^^^^^^^^^^^^^^^
  File "C:\Users\vg8rw\OneDrive\桌面\project\Test\test\Lib\site-packages\sqlalchemy\engine\base.py", line 3302, in raw_connection
    return self.pool.connect()
           ^^^^^^^^^^^^^^^^^^^
  File "C:\Users\vg8rw\OneDrive\桌面\project\Test\test\Lib\site-packages\sqlalchemy\pool\base.py", line 449, in connect
    return _ConnectionFairy._checkout(self)
           ^^^^^^^^^^^^^^^^^^^^^^^^^^^^^^^^
  File "C:\Users\vg8rw\OneDrive\桌面\project\Test\test\Lib\site-packages\sqlalchemy\pool\base.py", line 1263, in _checkout
    fairy = _ConnectionRecord.checkout(pool)
            ^^^^^^^^^^^^^^^^^^^^^^^^^^^^^^^^
  File "C:\Users\vg8rw\OneDrive\桌面\project\Test\test\Lib\site-packages\sqlalchemy\pool\base.py", line 712, in checkout
    rec = pool._do_get()
          ^^^^^^^^^^^^^^
  File "C:\Users\vg8rw\OneDrive\桌面\project\Test\test\Lib\site-packages\sqlalchemy\pool\impl.py", line 179, in _do_get
    with util.safe_reraise():
         ^^^^^^^^^^^^^^^^^^^
  File "C:\Users\vg8rw\OneDrive\桌面\project\Test\test\Lib\site-packages\sqlalchemy\util\langhelpers.py", line 146, in __exit__
    raise exc_value.with_traceback(exc_tb)
  File "C:\Users\vg8rw\OneDrive\桌面\project\Test\test\Lib\site-packages\sqlalchemy\pool\impl.py", line 177, in _do_get
    return self._create_connection()
           ^^^^^^^^^^^^^^^^^^^^^^^^^
  File "C:\Users\vg8rw\OneDrive\桌面\project\Test\test\Lib\site-packages\sqlalchemy\pool\base.py", line 390, in _create_connection
    return _ConnectionRecord(self)
           ^^^^^^^^^^^^^^^^^^^^^^^
  File "C:\Users\vg8rw\OneDrive\桌面\project\Test\test\Lib\site-packages\sqlalchemy\pool\base.py", line 674, in __init__
    self.__connect()
  File "C:\Users\vg8rw\OneDrive\桌面\project\Test\test\Lib\site-packages\sqlalchemy\pool\base.py", line 900, in __connect
    with util.safe_reraise():
         ^^^^^^^^^^^^^^^^^^^
  File "C:\Users\vg8rw\OneDrive\桌面\project\Test\test\Lib\site-packages\sqlalchemy\util\langhelpers.py", line 146, in __exit__
    raise exc_value.with_traceback(exc_tb)
  File "C:\Users\vg8rw\OneDrive\桌面\project\Test\test\Lib\site-packages\sqlalchemy\pool\base.py", line 896, in __connect
    self.dbapi_connection = connection = pool._invoke_creator(self)
                                         ^^^^^^^^^^^^^^^^^^^^^^^^^^
  File "C:\Users\vg8rw\OneDrive\桌面\project\Test\test\Lib\site-packages\sqlalchemy\engine\create.py", line 643, in connect
    return dialect.connect(*cargs, **cparams)
           ^^^^^^^^^^^^^^^^^^^^^^^^^^^^^^^^^^
  File "C:\Users\vg8rw\OneDrive\桌面\project\Test\test\Lib\site-packages\sqlalchemy\engine\default.py", line 621, in connect
    return self.loaded_dbapi.connect(*cargs, **cparams)
           ^^^^^^^^^^^^^^^^^^^^^^^^^^^^^^^^^^^^^^^^^^^^
  File "C:\Users\vg8rw\OneDrive\桌面\project\Test\test\Lib\site-packages\psycopg2\__init__.py", line 122, in connect
    conn = _connect(dsn, connection_factory=connection_factory, **kwasync)
           ^^^^^^^^^^^^^^^^^^^^^^^^^^^^^^^^^^^^^^^^^^^^^^^^^^^^^^^^^^^^^^^
psycopg2.OperationalError: connection to server at "35.221.226.168", port 5432 failed: Connection timed out (0x0000274C/10060)
	Is the server running on that host and accepting TCP/IP connections?


The above exception was the direct cause of the following exception:

Traceback (most recent call last):
  File "C:\Users\vg8rw\OneDrive\桌面\project\Test\test.py", line 351, in <module>
    schedule.run_pending()
  File "C:\Users\vg8rw\OneDrive\桌面\project\Test\test\Lib\site-packages\schedule\__init__.py", line 854, in run_pending
    default_scheduler.run_pending()
  File "C:\Users\vg8rw\OneDrive\桌面\project\Test\test\Lib\site-packages\schedule\__init__.py", line 101, in run_pending
    self._run_job(job)
  File "C:\Users\vg8rw\OneDrive\桌面\project\Test\test\Lib\site-packages\schedule\__init__.py", line 173, in _run_job
    ret = job.run()
          ^^^^^^^^^
  File "C:\Users\vg8rw\OneDrive\桌面\project\Test\test\Lib\site-packages\schedule\__init__.py", line 691, in run
    ret = self.job_func()
          ^^^^^^^^^^^^^^^
  File "C:\Users\vg8rw\OneDrive\桌面\project\Test\test.py", line 316, in scheduled_equipment
    data = get_equipment()
           ^^^^^^^^^^^^^^^
  File "C:\Users\vg8rw\OneDrive\桌面\project\Test\test.py", line 156, in get_equipment
    results = query.all()
              ^^^^^^^^^^^
  File "C:\Users\vg8rw\OneDrive\桌面\project\Test\test\Lib\site-packages\sqlalchemy\orm\query.py", line 2673, in all
    return self._iter().all()  # type: ignore
           ^^^^^^^^^^^^
  File "C:\Users\vg8rw\OneDrive\桌面\project\Test\test\Lib\site-packages\sqlalchemy\orm\query.py", line 2827, in _iter
    result: Union[ScalarResult[_T], Result[_T]] = self.session.execute(
                                                  ^^^^^^^^^^^^^^^^^^^^^
  File "C:\Users\vg8rw\OneDrive\桌面\project\Test\test\Lib\site-packages\sqlalchemy\orm\session.py", line 2362, in execute
    return self._execute_internal(
           ^^^^^^^^^^^^^^^^^^^^^^^
  File "C:\Users\vg8rw\OneDrive\桌面\project\Test\test\Lib\site-packages\sqlalchemy\orm\session.py", line 2237, in _execute_internal
    conn = self._connection_for_bind(bind)
           ^^^^^^^^^^^^^^^^^^^^^^^^^^^^^^^
  File "C:\Users\vg8rw\OneDrive\桌面\project\Test\test\Lib\site-packages\sqlalchemy\orm\session.py", line 2106, in _connection_for_bind
    return trans._connection_for_bind(engine, execution_options)
           ^^^^^^^^^^^^^^^^^^^^^^^^^^^^^^^^^^^^^^^^^^^^^^^^^^^^^
  File "<string>", line 2, in _connection_for_bind
  File "C:\Users\vg8rw\OneDrive\桌面\project\Test\test\Lib\site-packages\sqlalchemy\orm\state_changes.py", line 139, in _go
    ret_value = fn(self, *arg, **kw)
                ^^^^^^^^^^^^^^^^^^^^
  File "C:\Users\vg8rw\OneDrive\桌面\project\Test\test\Lib\site-packages\sqlalchemy\orm\session.py", line 1189, in _connection_for_bind
    conn = bind.connect()
           ^^^^^^^^^^^^^^
  File "C:\Users\vg8rw\OneDrive\桌面\project\Test\test\Lib\site-packages\sqlalchemy\engine\base.py", line 3278, in connect
    return self._connection_cls(self)
           ^^^^^^^^^^^^^^^^^^^^^^^^^^
  File "C:\Users\vg8rw\OneDrive\桌面\project\Test\test\Lib\site-packages\sqlalchemy\engine\base.py", line 148, in __init__
    Connection._handle_dbapi_exception_noconnection(
  File "C:\Users\vg8rw\OneDrive\桌面\project\Test\test\Lib\site-packages\sqlalchemy\engine\base.py", line 2442, in _handle_dbapi_exception_noconnection
    raise sqlalchemy_exception.with_traceback(exc_info[2]) from e
  File "C:\Users\vg8rw\OneDrive\桌面\project\Test\test\Lib\site-packages\sqlalchemy\engine\base.py", line 146, in __init__
    self._dbapi_connection = engine.raw_connection()
                             ^^^^^^^^^^^^^^^^^^^^^^^
  File "C:\Users\vg8rw\OneDrive\桌面\project\Test\test\Lib\site-packages\sqlalchemy\engine\base.py", line 3302, in raw_connection
    return self.pool.connect()
           ^^^^^^^^^^^^^^^^^^^
  File "C:\Users\vg8rw\OneDrive\桌面\project\Test\test\Lib\site-packages\sqlalchemy\pool\base.py", line 449, in connect
    return _ConnectionFairy._checkout(self)
           ^^^^^^^^^^^^^^^^^^^^^^^^^^^^^^^^
  File "C:\Users\vg8rw\OneDrive\桌面\project\Test\test\Lib\site-packages\sqlalchemy\pool\base.py", line 1263, in _checkout
    fairy = _ConnectionRecord.checkout(pool)
            ^^^^^^^^^^^^^^^^^^^^^^^^^^^^^^^^
  File "C:\Users\vg8rw\OneDrive\桌面\project\Test\test\Lib\site-packages\sqlalchemy\pool\base.py", line 712, in checkout
    rec = pool._do_get()
          ^^^^^^^^^^^^^^
  File "C:\Users\vg8rw\OneDrive\桌面\project\Test\test\Lib\site-packages\sqlalchemy\pool\impl.py", line 179, in _do_get
    with util.safe_reraise():
         ^^^^^^^^^^^^^^^^^^^
  File "C:\Users\vg8rw\OneDrive\桌面\project\Test\test\Lib\site-packages\sqlalchemy\util\langhelpers.py", line 146, in __exit__
    raise exc_value.with_traceback(exc_tb)
  File "C:\Users\vg8rw\OneDrive\桌面\project\Test\test\Lib\site-packages\sqlalchemy\pool\impl.py", line 177, in _do_get
    return self._create_connection()
           ^^^^^^^^^^^^^^^^^^^^^^^^^
  File "C:\Users\vg8rw\OneDrive\桌面\project\Test\test\Lib\site-packages\sqlalchemy\pool\base.py", line 390, in _create_connection
    return _ConnectionRecord(self)
           ^^^^^^^^^^^^^^^^^^^^^^^
  File "C:\Users\vg8rw\OneDrive\桌面\project\Test\test\Lib\site-packages\sqlalchemy\pool\base.py", line 674, in __init__
    self.__connect()
  File "C:\Users\vg8rw\OneDrive\桌面\project\Test\test\Lib\site-packages\sqlalchemy\pool\base.py", line 900, in __connect
    with util.safe_reraise():
         ^^^^^^^^^^^^^^^^^^^
  File "C:\Users\vg8rw\OneDrive\桌面\project\Test\test\Lib\site-packages\sqlalchemy\util\langhelpers.py", line 146, in __exit__
    raise exc_value.with_traceback(exc_tb)
  File "C:\Users\vg8rw\OneDrive\桌面\project\Test\test\Lib\site-packages\sqlalchemy\pool\base.py", line 896, in __connect
    self.dbapi_connection = connection = pool._invoke_creator(self)
                                         ^^^^^^^^^^^^^^^^^^^^^^^^^^
  File "C:\Users\vg8rw\OneDrive\桌面\project\Test\test\Lib\site-packages\sqlalchemy\engine\create.py", line 643, in connect
    return dialect.connect(*cargs, **cparams)
           ^^^^^^^^^^^^^^^^^^^^^^^^^^^^^^^^^^
  File "C:\Users\vg8rw\OneDrive\桌面\project\Test\test\Lib\site-packages\sqlalchemy\engine\default.py", line 621, in connect
    return self.loaded_dbapi.connect(*cargs, **cparams)
           ^^^^^^^^^^^^^^^^^^^^^^^^^^^^^^^^^^^^^^^^^^^^
  File "C:\Users\vg8rw\OneDrive\桌面\project\Test\test\Lib\site-packages\psycopg2\__init__.py", line 122, in connect
    conn = _connect(dsn, connection_factory=connection_factory, **kwasync)
           ^^^^^^^^^^^^^^^^^^^^^^^^^^^^^^^^^^^^^^^^^^^^^^^^^^^^^^^^^^^^^^^
sqlalchemy.exc.OperationalError: (psycopg2.OperationalError) connection to server at "35.221.226.168", port 5432 failed: Connection timed out (0x0000274C/10060)
	Is the server running on that host and accepting TCP/IP connections?

(Background on this error at: https://sqlalche.me/e/20/e3q8)
Traceback (most recent call last):
  File "C:\Users\vg8rw\OneDrive\桌面\project\Test\test\Lib\site-packages\sqlalchemy\engine\base.py", line 1967, in _exec_single_context
    self.dialect.do_execute(
  File "C:\Users\vg8rw\OneDrive\桌面\project\Test\test\Lib\site-packages\sqlalchemy\engine\default.py", line 941, in do_execute
    cursor.execute(statement, parameters)
psycopg2.OperationalError: server closed the connection unexpectedly
	This probably means the server terminated abnormally
	before or while processing the request.
server closed the connection unexpectedly
	This probably means the server terminated abnormally
	before or while processing the request.


The above exception was the direct cause of the following exception:

Traceback (most recent call last):
  File "C:\Users\vg8rw\OneDrive\桌面\project\Test\test.py", line 351, in <module>
    schedule.run_pending()
  File "C:\Users\vg8rw\OneDrive\桌面\project\Test\test\Lib\site-packages\schedule\__init__.py", line 854, in run_pending
    default_scheduler.run_pending()
  File "C:\Users\vg8rw\OneDrive\桌面\project\Test\test\Lib\site-packages\schedule\__init__.py", line 101, in run_pending
    self._run_job(job)
  File "C:\Users\vg8rw\OneDrive\桌面\project\Test\test\Lib\site-packages\schedule\__init__.py", line 173, in _run_job
    ret = job.run()
          ^^^^^^^^^
  File "C:\Users\vg8rw\OneDrive\桌面\project\Test\test\Lib\site-packages\schedule\__init__.py", line 691, in run
    ret = self.job_func()
          ^^^^^^^^^^^^^^^
  File "C:\Users\vg8rw\OneDrive\桌面\project\Test\test.py", line 316, in scheduled_equipment
    data = get_equipment()
           ^^^^^^^^^^^^^^^
  File "C:\Users\vg8rw\OneDrive\桌面\project\Test\test.py", line 156, in get_equipment
    results = query.all()
              ^^^^^^^^^^^
  File "C:\Users\vg8rw\OneDrive\桌面\project\Test\test\Lib\site-packages\sqlalchemy\orm\query.py", line 2673, in all
    return self._iter().all()  # type: ignore
           ^^^^^^^^^^^^
  File "C:\Users\vg8rw\OneDrive\桌面\project\Test\test\Lib\site-packages\sqlalchemy\orm\query.py", line 2827, in _iter
    result: Union[ScalarResult[_T], Result[_T]] = self.session.execute(
                                                  ^^^^^^^^^^^^^^^^^^^^^
  File "C:\Users\vg8rw\OneDrive\桌面\project\Test\test\Lib\site-packages\sqlalchemy\orm\session.py", line 2362, in execute
    return self._execute_internal(
           ^^^^^^^^^^^^^^^^^^^^^^^
  File "C:\Users\vg8rw\OneDrive\桌面\project\Test\test\Lib\site-packages\sqlalchemy\orm\session.py", line 2247, in _execute_internal
    result: Result[Any] = compile_state_cls.orm_execute_statement(
                          ^^^^^^^^^^^^^^^^^^^^^^^^^^^^^^^^^^^^^^^^
  File "C:\Users\vg8rw\OneDrive\桌面\project\Test\test\Lib\site-packages\sqlalchemy\orm\context.py", line 305, in orm_execute_statement
    result = conn.execute(
             ^^^^^^^^^^^^^
  File "C:\Users\vg8rw\OneDrive\桌面\project\Test\test\Lib\site-packages\sqlalchemy\engine\base.py", line 1418, in execute
    return meth(
           ^^^^^
  File "C:\Users\vg8rw\OneDrive\桌面\project\Test\test\Lib\site-packages\sqlalchemy\sql\elements.py", line 515, in _execute_on_connection
    return connection._execute_clauseelement(
           ^^^^^^^^^^^^^^^^^^^^^^^^^^^^^^^^^^
  File "C:\Users\vg8rw\OneDrive\桌面\project\Test\test\Lib\site-packages\sqlalchemy\engine\base.py", line 1640, in _execute_clauseelement
    ret = self._execute_context(
          ^^^^^^^^^^^^^^^^^^^^^^
  File "C:\Users\vg8rw\OneDrive\桌面\project\Test\test\Lib\site-packages\sqlalchemy\engine\base.py", line 1846, in _execute_context
    return self._exec_single_context(
           ^^^^^^^^^^^^^^^^^^^^^^^^^^
  File "C:\Users\vg8rw\OneDrive\桌面\project\Test\test\Lib\site-packages\sqlalchemy\engine\base.py", line 1986, in _exec_single_context
    self._handle_dbapi_exception(
  File "C:\Users\vg8rw\OneDrive\桌面\project\Test\test\Lib\site-packages\sqlalchemy\engine\base.py", line 2355, in _handle_dbapi_exception
    raise sqlalchemy_exception.with_traceback(exc_info[2]) from e
  File "C:\Users\vg8rw\OneDrive\桌面\project\Test\test\Lib\site-packages\sqlalchemy\engine\base.py", line 1967, in _exec_single_context
    self.dialect.do_execute(
  File "C:\Users\vg8rw\OneDrive\桌面\project\Test\test\Lib\site-packages\sqlalchemy\engine\default.py", line 941, in do_execute
    cursor.execute(statement, parameters)
sqlalchemy.exc.OperationalError: (psycopg2.OperationalError) server closed the connection unexpectedly
	This probably means the server terminated abnormally
	before or while processing the request.
server closed the connection unexpectedly
	This probably means the server terminated abnormally
	before or while processing the request.

[SQL: SELECT DISTINCT ON (data_collection.test_preprocess_main_data."dataloggerSN") data_collection.test_preprocess_main_data."dataloggerSN" AS "data_collection_test_preprocess_main_data_dataloggerSN", data_collection.test_preprocess_main_data."內部溫度" AS "data_collection_test_preprocess_main_data_內部溫度", data_collection.test_preprocess_main_data.brand AS data_collection_test_preprocess_main_data_brand, data_collection.test_preprocess_main_data.device_type AS data_collection_test_preprocess_main_data_device_type, data_collection.test_preprocess_main_data.modbus_addr AS data_collection_test_preprocess_main_data_modbus_addr, data_collection.test_preprocess_main_data."SN" AS "data_collection_test_preprocess_main_data_SN", data_collection.test_preprocess_main_data."狀態1" AS "data_collection_test_preprocess_main_data_狀態1", data_collection.test_preprocess_main_data."告警1" AS "data_collection_test_preprocess_main_data_告警1", data_collection.test_preprocess_main_data.time AS data_collection_test_preprocess_main_data_time 
FROM data_collection.test_preprocess_main_data 
WHERE data_collection.test_preprocess_main_data."dataloggerSN" = %(dataloggerSN_1)s ORDER BY data_collection.test_preprocess_main_data."dataloggerSN", data_collection.test_preprocess_main_data.time DESC]
[parameters: {'dataloggerSN_1': '10132230202714'}]
(Background on this error at: https://sqlalche.me/e/20/e3q8)
